##[group]Run Mergifyio/add-linear-author-as-reviewer@main
with:
  GITHUB_TOKEN:
  LINEAR_API_KEY:
  EMAIL_MAPPING: jd@mergify.com jd
sileht@mergify.com sileht
fabien.martinet@mergify.com Syffe
alexandre.gaubert@mergify.com AlexandreGaubert
charly.laurent@mergify.com DouglasBlackwood
guillaume.risbourg@mergify.com Greesb
leo.ecrepont@mergify.com lecrepont01
damien.couppe@mergify.com Kontrolix
samuel.billaud@mergify.com samuelbillaud
##[endgroup]
##[group]Run python3 -m venv venv
python3 -m venv venv
venv/bin/pip install httpx
venv/bin/python /home/runner/work/_actions/Mergifyio/add-linear-author-as-reviewer/main/linear-extract-reviewers.py >> $GITHUB_OUTPUT
shell: /usr/bin/bash --noprofile --norc -e -o pipefail {0}
env:
  INPUT_LINEAR_API_KEY:
  INPUT_EMAIL_MAPPING: jd@mergify.com jd
sileht@mergify.com sileht
fabien.martinet@mergify.com Syffe
alexandre.gaubert@mergify.com AlexandreGaubert
charly.laurent@mergify.com DouglasBlackwood
guillaume.risbourg@mergify.com Greesb
leo.ecrepont@mergify.com lecrepont01
damien.couppe@mergify.com Kontrolix
samuel.billaud@mergify.com samuelbillaud
  INPUT_PULL_REQUEST_BODY: Fixes MRGFY-1672
Change-Id: Icc856f9acf20252e1e8cddad0ba196229636b3fd
##[endgroup]
Collecting httpx
  Downloading httpx-0.25.0-py3-none-any.whl (75 kB)
      75.7/75.7 KB 2.1 MB/s eta 0:00:00
Collecting idna
  Downloading idna-3.4-py3-none-any.whl (61 kB)
      61.5/61.5 KB 5.6 MB/s eta 0:00:00
Collecting httpcore<0.19.0,>=0.18.0
  Downloading httpcore-0.18.0-py3-none-any.whl (76 kB)
      76.0/76.0 KB 6.6 MB/s eta 0:00:00
Collecting certifi
  Downloading certifi-2023.7.22-py3-none-any.whl (158 kB)
      158.3/158.3 KB 8.2 MB/s eta 0:00:00
Collecting sniffio
  Downloading sniffio-1.3.0-py3-none-any.whl (10 kB)
Collecting h11<0.15,>=0.13
  Downloading h11-0.14.0-py3-none-any.whl (58 kB)
      58.3/58.3 KB 7.7 MB/s eta 0:00:00
Collecting anyio<5.0,>=3.0
  Downloading anyio-4.0.0-py3-none-any.whl (83 kB)
      83.1/83.1 KB 10.5 MB/s eta 0:00:00
Collecting exceptiongroup>=1.0.2
  Downloading exceptiongroup-1.1.3-py3-none-any.whl (14 kB)
Installing collected packages: sniffio, idna, h11, exceptiongroup, certifi, anyio, httpcore, httpx
Successfully installed anyio-4.0.0 certifi-2023.7.22 exceptiongroup-1.1.3 h11-0.14.0 httpcore-0.18.0 httpx-0.25.0 idna-3.4 sniffio-1.3.0
{'query': 'query { MRGFY_1672: issue(id: "MRGFY-1672") { creator { email } }  }'}
Traceback (most recent call last):
  File "/home/runner/work/engine/engine/venv/lib/python3.10/site-packages/httpcore/_exceptions.py", line 10, in map_exceptions
    yield
  File "/home/runner/work/engine/engine/venv/lib/python3.10/site-packages/httpcore/_backends/sync.py", line 126, in read
    return self._sock.recv(max_bytes)
  File "/usr/lib/python3.10/ssl.py", line 1259, in recv
    return self.read(buflen)
  File "/usr/lib/python3.10/ssl.py", line 1132, in read
    return self._sslobj.read(len)
TimeoutError: The read operation timed out
The above exception was the direct cause of the following exception:
Traceback (most recent call last):
  File "/home/runner/work/engine/engine/venv/lib/python3.10/site-packages/httpx/_transports/default.py", line 66, in map_httpcore_exceptions
    yield
  File "/home/runner/work/engine/engine/venv/lib/python3.10/site-packages/httpx/_transports/default.py", line 228, in handle_request
    resp = self._pool.handle_request(req)
  File "/home/runner/work/engine/engine/venv/lib/python3.10/site-packages/httpcore/_sync/connection_pool.py", line 262, in handle_request
    raise exc
  File "/home/runner/work/engine/engine/venv/lib/python3.10/site-packages/httpcore/_sync/connection_pool.py", line 245, in handle_request
    response = connection.handle_request(request)
  File "/home/runner/work/engine/engine/venv/lib/python3.10/site-packages/httpcore/_sync/connection.py", line 103, in handle_request
    return self._connection.handle_request(request)
  File "/home/runner/work/engine/engine/venv/lib/python3.10/site-packages/httpcore/_sync/http11.py", line 133, in handle_request
    raise exc
  File "/home/runner/work/engine/engine/venv/lib/python3.10/site-packages/httpcore/_sync/http11.py", line 111, in handle_request
    ) = self._receive_response_headers(kwargs)
  File "/home/runner/work/engine/engine/venv/lib/python3.10/site-packages/httpcore/_sync/http11.py", line 176, in _receive_response_headers
    event = self._receive_event(timeout=timeout)
  File "/home/runner/work/engine/engine/venv/lib/python3.10/site-packages/httpcore/_sync/http11.py", line 212, in _receive_event
    data = self._network_stream.read(
  File "/home/runner/work/engine/engine/venv/lib/python3.10/site-packages/httpcore/_backends/sync.py", line 124, in read
    with map_exceptions(exc_map):
  File "/usr/lib/python3.10/contextlib.py", line 153, in __exit__
    self.gen.throw(typ, value, traceback)
  File "/home/runner/work/engine/engine/venv/lib/python3.10/site-packages/httpcore/_exceptions.py", line 14, in map_exceptions
    raise to_exc(exc) from exc
httpcore.ReadTimeout: The read operation timed out
The above exception was the direct cause of the following exception:
Traceback (most recent call last):
  File "/home/runner/work/_actions/Mergifyio/add-linear-author-as-reviewer/main/linear-extract-reviewers.py", line 52, in <module>
    main()
  File "/home/runner/work/_actions/Mergifyio/add-linear-author-as-reviewer/main/linear-extract-reviewers.py", line 38, in main
    responses = linear.post("/graphql", json=query).json()
  File "/home/runner/work/engine/engine/venv/lib/python3.10/site-packages/httpx/_client.py", line 1132, in post
    return self.request(
  File "/home/runner/work/engine/engine/venv/lib/python3.10/site-packages/httpx/_client.py", line 814, in request
    return self.send(request, auth=auth, follow_redirects=follow_redirects)
  File "/home/runner/work/engine/engine/venv/lib/python3.10/site-packages/httpx/_client.py", line 901, in send
    response = self._send_handling_auth(
  File "/home/runner/work/engine/engine/venv/lib/python3.10/site-packages/httpx/_client.py", line 929, in _send_handling_auth
    response = self._send_handling_redirects(
  File "/home/runner/work/engine/engine/venv/lib/python3.10/site-packages/httpx/_client.py", line 966, in _send_handling_redirects
    response = self._send_single_request(request)
  File "/home/runner/work/engine/engine/venv/lib/python3.10/site-packages/httpx/_client.py", line 1002, in _send_single_request
    response = transport.handle_request(request)
  File "/home/runner/work/engine/engine/venv/lib/python3.10/site-packages/httpx/_transports/default.py", line 227, in handle_request
    with map_httpcore_exceptions():
  File "/usr/lib/python3.10/contextlib.py", line 153, in __exit__
    self.gen.throw(typ, value, traceback)
  File "/home/runner/work/engine/engine/venv/lib/python3.10/site-packages/httpx/_transports/default.py", line 83, in map_httpcore_exceptions
    raise mapped_exc(message) from exc
httpx.ReadTimeout: The read operation timed out
##[error]Process completed with exit code 1.